<!--- NOTE! THIS FILE IS AUTOMATICALLY GENERATED, IF YOU ARE READING THIS, YOU ARE EDITING THE WRONG FILE --->
**usbtool**: https://github.com/jakeogh/usbtool
### Installation:

#### Debian 11

    1. sudo apt-get install python3-pip -y

    2. pip install --force-reinstall git+https://git@github.com/jakeogh/usbtool

    3. source ~/.profile

### Examples:
```
$ usbtool find-device --help
Usage: usbtool find-device [OPTIONS]

Options:
  --command-hex TEXT
  --response-hex TEXT
  --usb-id TEXT
  --serial-number TEXT
  --manufacturer TEXT
  --data-dir DIRECTORY  [default: /home/user/.usbtool/2025_02_28]
  --baud-rate INTEGER   [default: 9600]
  --log-serial-data
  --timeout INTEGER     [default: 1]
  --verbose
  --dict
  --verbose-inf
  --help                Show this message and exit.

$ usbtool find-device --baud-rate 921600 --command-hex 100253411003 --response-hex 065341
serial_url='spy:///dev/ttyUSB1?file=/dev/null'
_tx_bytes=b'\x10\x02SA\x10\x03'
_bytes_read=b'' _expected_rx_bytes=b'\x06SA'
serial_url='spy:///dev/ttyUSB0?file=/dev/null'
_tx_bytes=b'\x10\x02SA\x10\x03'
_bytes_read=b'\x06SA' _expected_rx_bytes=b'\x06SA'
¬/dev/ttyUSB0
$ usbtool find-device --serial-number DA1ZDECW
Traceback (most recent call last):
  File "/usr/lib/python-exec/python3.12/usbtool", line 8, in <module>
    sys.exit(cli())
             ^^^^^
  File "/usr/lib/python3.12/site-packages/click/core.py", line 1161, in __call__
    return self.main(*args, **kwargs)
           ^^^^^^^^^^^^^^^^^^^^^^^^^^
  File "/usr/lib/python3.12/site-packages/click/core.py", line 1082, in main
    rv = self.invoke(ctx)
         ^^^^^^^^^^^^^^^^
  File "/usr/lib/python3.12/site-packages/click/core.py", line 1697, in invoke
    return _process_result(sub_ctx.command.invoke(sub_ctx))
                           ^^^^^^^^^^^^^^^^^^^^^^^^^^^^^^^
  File "/usr/lib/python3.12/site-packages/click/core.py", line 1443, in invoke
    return ctx.invoke(self.callback, **ctx.params)
           ^^^^^^^^^^^^^^^^^^^^^^^^^^^^^^^^^^^^^^^
  File "/usr/lib/python3.12/site-packages/click/core.py", line 788, in invoke
    return __callback(*args, **kwargs)
           ^^^^^^^^^^^^^^^^^^^^^^^^^^^
  File "/usr/lib/python3.12/site-packages/click/decorators.py", line 33, in new_func
    return f(get_current_context(), *args, **kwargs)
           ^^^^^^^^^^^^^^^^^^^^^^^^^^^^^^^^^^^^^^^^^
  File "/usr/lib/python3.12/site-packages/usbtool/usbtool.py", line 337, in _find_device
    _ = find_device(
        ^^^^^^^^^^^^
  File "/usr/lib/python3.12/site-packages/usbtool/usbtool.py", line 169, in find_device
    _serial_number = get_serial_number_for_device(_)
                     ^^^^^^^^^^^^^^^^^^^^^^^^^^^^^^^
  File "/usr/lib/python3.12/site-packages/usbtool/usbtool.py", line 58, in get_serial_number_for_device
    _ = sh.udevadm("info", "--attribute-walk", device.as_posix())
        ^^^^^^^^^^^^^^^^^^^^^^^^^^^^^^^^^^^^^^^^^^^^^^^^^^^^^^^^^
  File "/usr/lib/python3.12/site-packages/sh.py", line 1511, in __call__
    rc = self.__class__.RunningCommandCls(cmd, call_args, stdin, stdout, stderr)
         ^^^^^^^^^^^^^^^^^^^^^^^^^^^^^^^^^^^^^^^^^^^^^^^^^^^^^^^^^^^^^^^^^^^^^^^
  File "/usr/lib/python3.12/site-packages/sh.py", line 734, in __init__
    self.wait()
  File "/usr/lib/python3.12/site-packages/sh.py", line 796, in wait
    self.handle_command_exit_code(exit_code)
  File "/usr/lib/python3.12/site-packages/sh.py", line 823, in handle_command_exit_code
    raise exc
sh.ErrorReturnCode_1: 

  RAN: /usr/bin/udevadm info --attribute-walk /dev/ttyACM0

  STDOUT:


  STDERR:
Unknown device "/dev/ttyACM0": No such device


```
