<!--- NOTE! THIS FILE IS AUTOMATICALLY GENERATED, IF YOU ARE READING THIS, YOU ARE EDITING THE WRONG FILE --->
**usbtool**: https://github.com/jakeogh/usbtool
### Installation:

#### Debian 11

    1. sudo apt-get install python3-pip -y

    2. pip install --force-reinstall git+https://git@github.com/jakeogh/usbtool

    3. source ~/.profile

### Examples:
```
$ usbtool find-device --help
Usage: usbtool find-device [OPTIONS]

Options:
  --command-hex TEXT
  --response-hex TEXT
  --usb-id TEXT
  --serial-number TEXT
  --data-dir DIRECTORY  [default: /home/user/.usbtool/2025_02_28]
  --baud-rate INTEGER   [default: 9600]
  --log-serial-data
  --timeout INTEGER     [default: 1]
  --verbose
  --dict
  --verbose-inf
  --help                Show this message and exit.

$ usbtool find-device --baud-rate 921600 --command-hex 100253411003 --response-hex 065341
serial_url='spy:///dev/ttyUSB1?file=/dev/null'
_tx_bytes=b'\x10\x02SA\x10\x03'
_bytes_read=b'' _expected_rx_bytes=b'\x06SA'
serial_url='spy:///dev/ttyUSB0?file=/dev/null'
_tx_bytes=b'\x10\x02SA\x10\x03'
_bytes_read=b'\r\n\rSDHC card has been successfully initialized !!!\r\n\r\r\n\rFAT filesystem mounted !!!\r\n\rcalling GPIO1_Init()\r\ncalling LED_Init()\r\nInitializing Timers...\r\nInitializing K70 ADC0...\r\nCalibrating K70 ADC0...\r\nK70 ADC0 Calibrated\r\nSetting ADC0/ADC1 CONVST HIGH (not converting)...\r\nInitializing K70 DACs...\r\ncalling init_ethernet()...\r\nInitializing Ethernet device (waiting for link light)...\r\nvInitENET()\r\r\nprvInitialiseENETBuffers()\r\r\nvInitENET() after prvInitialiseENETBuffers()\r\r\nvInitENET() calling mii_read()\r\r\nvInitENET() after calling mii_read()\r\r\nvInitENET() calling mii_write()\r\r\nvInitENET() waiting for auto negotiate to complete\r\r\n' _expected_rx_bytes=b'\x06SA'
Traceback (most recent call last):
  File "/usr/lib/python-exec/python3.12/usbtool", line 8, in <module>
    sys.exit(cli())
             ^^^^^
  File "/usr/lib/python3.12/site-packages/click/core.py", line 1161, in __call__
    return self.main(*args, **kwargs)
           ^^^^^^^^^^^^^^^^^^^^^^^^^^
  File "/usr/lib/python3.12/site-packages/click/core.py", line 1082, in main
    rv = self.invoke(ctx)
         ^^^^^^^^^^^^^^^^
  File "/usr/lib/python3.12/site-packages/click/core.py", line 1697, in invoke
    return _process_result(sub_ctx.command.invoke(sub_ctx))
                           ^^^^^^^^^^^^^^^^^^^^^^^^^^^^^^^
  File "/usr/lib/python3.12/site-packages/click/core.py", line 1443, in invoke
    return ctx.invoke(self.callback, **ctx.params)
           ^^^^^^^^^^^^^^^^^^^^^^^^^^^^^^^^^^^^^^^
  File "/usr/lib/python3.12/site-packages/click/core.py", line 788, in invoke
    return __callback(*args, **kwargs)
           ^^^^^^^^^^^^^^^^^^^^^^^^^^^
  File "/usr/lib/python3.12/site-packages/click/decorators.py", line 33, in new_func
    return f(get_current_context(), *args, **kwargs)
           ^^^^^^^^^^^^^^^^^^^^^^^^^^^^^^^^^^^^^^^^^
  File "/usr/lib/python3.12/site-packages/usbtool/usbtool.py", line 310, in _find_device
    _ = find_device(
        ^^^^^^^^^^^^
  File "/usr/lib/python3.12/site-packages/usbtool/usbtool.py", line 186, in find_device
    raise ValueError(
ValueError: Error: No matching device found for command_hex='100253411003' response_hex='065341' baud_rate=921600 usb_id=None serial_number=None timeout=1

$ usbtool find-device --serial-number DA1ZDECW
Traceback (most recent call last):
  File "/usr/lib/python-exec/python3.12/usbtool", line 8, in <module>
    sys.exit(cli())
             ^^^^^
  File "/usr/lib/python3.12/site-packages/click/core.py", line 1161, in __call__
    return self.main(*args, **kwargs)
           ^^^^^^^^^^^^^^^^^^^^^^^^^^
  File "/usr/lib/python3.12/site-packages/click/core.py", line 1082, in main
    rv = self.invoke(ctx)
         ^^^^^^^^^^^^^^^^
  File "/usr/lib/python3.12/site-packages/click/core.py", line 1697, in invoke
    return _process_result(sub_ctx.command.invoke(sub_ctx))
                           ^^^^^^^^^^^^^^^^^^^^^^^^^^^^^^^
  File "/usr/lib/python3.12/site-packages/click/core.py", line 1443, in invoke
    return ctx.invoke(self.callback, **ctx.params)
           ^^^^^^^^^^^^^^^^^^^^^^^^^^^^^^^^^^^^^^^
  File "/usr/lib/python3.12/site-packages/click/core.py", line 788, in invoke
    return __callback(*args, **kwargs)
           ^^^^^^^^^^^^^^^^^^^^^^^^^^^
  File "/usr/lib/python3.12/site-packages/click/decorators.py", line 33, in new_func
    return f(get_current_context(), *args, **kwargs)
           ^^^^^^^^^^^^^^^^^^^^^^^^^^^^^^^^^^^^^^^^^
  File "/usr/lib/python3.12/site-packages/usbtool/usbtool.py", line 310, in _find_device
    _ = find_device(
        ^^^^^^^^^^^^
  File "/usr/lib/python3.12/site-packages/usbtool/usbtool.py", line 186, in find_device
    raise ValueError(
ValueError: Error: No matching device found for command_hex=None response_hex=None baud_rate=9600 usb_id=None serial_number='DA1ZDECW' timeout=1

```
